<?xml version='1.0'?>
<robot name="SphereX">        <!-- Give the base link a unique name -->
    <link name="SphereXOuter">
        <pose>0 0 1 1.57 0 0</pose>
        <inertial>
            <mass value="2.5"/>
            <inertia ixx="0.0" ixy="0.0" ixz="0.0" iyy="0.0" iyz="0.0" izz="0.0"/>
        </inertial>
        <visual name="bottom_visual">
            <geometry>
                <mesh filename="package://spherex/meshes/spherex_bot.dae"/>
            </geometry>
        </visual>

        <visual name="top_visual">
            <geometry>
                <mesh filename="package://spherex/meshes/spherex_top.dae"/>
            </geometry>
        </visual>

        <collision name="spherex_collision">
            <geometry>
                <sphere radius="0.25"/>
            </geometry>
        </collision>

    </link>

 <link name="SphereXMid">
    
        <!-- 
            <sensor name="my_ray_sensor" update_rate="20">
            <parent link="optical_frame_link_name"/>
            <origin xyz="0 0 0" rpy="0 0 0"/>
            <ray>
                <horizontal samples="100" resolution="1" min_angle="-1.5708" max_angle="1.5708"/>
                <vertical samples="1" resolution="1" min_angle="0" max_angle="0"/>
            </ray>
        </sensor> -->

        <!--
                <sensor type="ray" name="sensor">
                    <pose>0.25 0 0 0 0 0</pose>
                    <visualize>true</visualize>
                    <update_rate>30</update_rate>
                    <ray>
                        <scan>
                            <horizontal>
                                <samples>32</samples>
                                <resolution>1</resolution>
                                <min_angle>-0.5</min_angle>
                                <max_angle>0.5</max_angle>
                            </horizontal>
                        </scan>
                        <range>
                            <min>0.05</min>
                            <max>20</max>
                            <resolution>0.02</resolution>
                        </range>
                    </ray>
                </sensor>
        -->
        <pose>0 0 1 1.57 0 0</pose>
        <inertial>
            <mass value="0.5"/>
            <inertia ixx="0.0" ixy="0.0" ixz="0.0" iyy="0.0" iyz="0.0" izz="0.0"/>
        </inertial>

        <!-- The visual is mostly a copy of the collision -->
        <visual name="mid_visual">
            <geometry>
                <mesh filename="package://spherex/meshes/spherex_mid.dae"/>

            </geometry>
        </visual>
    </link>

    <joint name="center_pivot" type="continuous">
        <parent link="SphereXOuter" />
        <child link="SphereXMid"/>
        <axis xyz="0 0 1"/>
    </joint>
</robot>
